<?xml version="1.0" ?>
<!-- =================================================================================== -->
<!-- |    This document was autogenerated by xacro from cart.xacro                     | -->
<!-- |    EDITING THIS FILE BY HAND IS NOT RECOMMENDED                                 | -->
<!-- =================================================================================== -->
<robot name="cart">
  <material name="blue">
    <color rgba="0 0 0.8 0.5"/>
  </material>
  <material name="black">
    <color rgba="0 0 0 1"/>
  </material>
  <material name="white">
    <color rgba="1 1 1 1"/>
  </material>
  <link name="cart_base">
    <visual>
      <geometry>
        <box size="0.762 0.4064 0.2032"/>
      </geometry>
      <origin rpy="0 0 0" xyz="0 0 -0.0"/>
      <material name="blue"/>
    </visual>
    <collision>
      <geometry>
        <box size="0.762 0.4064 0.2032"/>
      </geometry>
    </collision>
    <inertial>
      <origin rpy="0 0 0" xyz="0 0 0.0"/>
      <mass value="18"/>
      <inertia ixx="1.11870744" ixy="0.0" ixz="0.0" iyy="0.3096768" iyz="0.0" izz="0.9329013600000001"/>
    </inertial>
  </link>
  <link name="right_front_wheel">
    <visual>
      <geometry>
        <cylinder length="0.09" radius="0.2667"/>
      </geometry>
      <origin rpy="0 1.57075 1.57075" xyz="0 0 0"/>
      <material name="white"/>
    </visual>
    <collision>
      <geometry>
        <cylinder length="0.09" radius="0.2667"/>
      </geometry>
      <origin rpy="0 1.57075 1.57075" xyz="0 0 0"/>
    </collision>
    <inertial>
      <origin rpy="0 0 0" xyz="0 0 0.0"/>
      <mass value="3.62874"/>
      <inertia ixx="0.06697646157465" ixy="0.0" ixz="0.0" iyy="0.06697646157465" iyz="0.0" izz="0.12905412414929998"/>
    </inertial>
  </link>
  <joint name="cart_to_right_front_wheel" type="revolute">
    <limit lower="-10000" upper="10000" effort="15" velocity="15"/>
    <axis rpy="0 0 0" xyz="0 1 0"/>
    <parent link="cart_base"/>
    <child link="right_front_wheel"/>
    <origin rpy="0 0 0" xyz="0.381 0.3022 -0.07815384615384614"/>
  </joint>
  <link name="left_front_wheel">
    <visual>
      <geometry>
        <cylinder length="0.09" radius="0.2667"/>
      </geometry>
      <origin rpy="0 1.57075 1.57075" xyz="0 0 0"/>
      <material name="white"/>
    </visual>
    <collision>
      <geometry>
        <cylinder length="0.09" radius="0.2667"/>
      </geometry>
      <origin rpy="0 1.57075 1.57075" xyz="0 0 0"/>
    </collision>
    <inertial>
      <origin rpy="0 0 0" xyz="0 0 0.0"/>
      <mass value="3.62874"/>
      <inertia ixx="0.06697646157465" ixy="0.0" ixz="0.0" iyy="0.06697646157465" iyz="0.0" izz="0.12905412414929998"/>
    </inertial>
  </link>
  <joint name="cart_to_left_front_wheel" type="revolute">
    <limit lower="-10000" upper="10000" effort="15" velocity="15"/>
    <axis rpy="0 0 0" xyz="0 1 0"/>
    <parent link="cart_base"/>
    <child link="left_front_wheel"/>
    <origin rpy="0 0 0" xyz="0.381 -0.3022 -0.07815384615384614"/>
  </joint>
  <link name="right_back_wheel">
    <visual>
      <geometry>
        <cylinder length="0.09" radius="0.2667"/>
      </geometry>
      <origin rpy="0 1.57075 1.57075" xyz="0 0 0"/>
      <material name="white"/>
    </visual>
    <collision>
      <geometry>
        <cylinder length="0.09" radius="0.2667"/>
      </geometry>
      <origin rpy="0 1.57075 1.57075" xyz="0 0 0"/>
    </collision>
    <inertial>
      <origin rpy="0 0 0" xyz="0 0 0.0"/>
      <mass value="3.62874"/>
      <inertia ixx="0.06697646157465" ixy="0.0" ixz="0.0" iyy="0.06697646157465" iyz="0.0" izz="0.12905412414929998"/>
    </inertial>
  </link>
  <joint name="cart_to_right_back_wheel" type="revolute">
    <limit lower="-10000" upper="10000" effort="15" velocity="15"/>
    <axis rpy="0 0 0" xyz="0 1 0"/>
    <parent link="cart_base"/>
    <child link="right_back_wheel"/>
    <origin rpy="0 0 0" xyz="-0.381 0.3022 -0.07815384615384614"/>
  </joint>
  <link name="left_back_wheel">
    <visual>
      <geometry>
        <cylinder length="0.09" radius="0.2667"/>
      </geometry>
      <origin rpy="0 1.57075 1.57075" xyz="0 0 0"/>
      <material name="white"/>
    </visual>
    <collision>
      <geometry>
        <cylinder length="0.09" radius="0.2667"/>
      </geometry>
      <origin rpy="0 1.57075 1.57075" xyz="0 0 0"/>
    </collision>
    <inertial>
      <origin rpy="0 0 0" xyz="0 0 0.0"/>
      <mass value="3.62874"/>
      <inertia ixx="0.06697646157465" ixy="0.0" ixz="0.0" iyy="0.06697646157465" iyz="0.0" izz="0.12905412414929998"/>
    </inertial>
  </link>
  <joint name="cart_to_left_back_wheel" type="revolute">
    <limit lower="-10000" upper="10000" effort="15" velocity="15"/>
    <axis rpy="0 0 0" xyz="0 1 0"/>
    <parent link="cart_base"/>
    <child link="left_back_wheel"/>
    <origin rpy="0 0 0" xyz="-0.381 -0.3022 -0.07815384615384614"/>
  </joint>

  <!-- <link name="pendulum">
    <visual>
      <geometry>
        <cylinder radius="0.02" length="0.4"/>
      </geometry>
      <origin rpy="0 0 0" xyz="0 0 0.2"/>
      <material name="black"/>
    </visual>

    <inertial>
      <origin rpy="0 0 0" xyz="0 0 0.2"/>
      <mass value="0.5"/>
      <inertia ixx="0.030000000000000006" ixy="0.0" ixz="0.0" iyy="0.030000000000000006" iyz="0.0" izz="0.030000000000000006"/>
    </inertial>
  </link>
  <joint name="pendulum" type="revolute">
    <axis rpy="0 0 0" xyz="0 1 0"/>
    <parent link="cart_base"/>
    <child link="pendulum"/>
    <origin rpy="0 0.1 0" xyz="0 0 0.15694736842105264"/>
  </joint> -->

  <link name="payload">
    <visual>
      <geometry>
        <box size="0.1 0.1 0.1"/>
      </geometry>
      <material name="black"/>
    </visual>
    <collision>
      <geometry>
        <box size="0.1 0.1 0.1"/>
      </geometry>
    </collision>
    <inertial>
      <origin rpy="0 0 0" xyz="0 0 0.0"/>
      <mass value="18"/>
      <inertia ixx="0.030000000000000006" ixy="0.0" ixz="0.0" iyy="0.030000000000000006" iyz="0.0" izz="0.030000000000000006"/>
    </inertial>
  </link>
  <joint name="payload" type="prismatic">
    <dynamics damping="0.05" friction="0.1"/>
    <limit lower="-0.25" upper="0.25" effort="100" velocity="10"/>
    <axis rpy="0 0 0" xyz="1 0 0"/>
    <parent link="cart_base"/>
    <child link="payload"/>
    <origin rpy="0 0 0" xyz="0 0 0.15694736842105264"/>
    <!-- <limit effort="100" lower="-0.381" upper="0.381" velocity="0.5"/> -->
  </joint>

</robot>

